FFFF...
======================================================================
FAIL: test_eval_1 (__main__.TestCollatz)
----------------------------------------------------------------------
Traceback (most recent call last):
  File "TestCollatz.py", line 42, in test_eval_1
    self.assertEqual(v, 20)
AssertionError: 1 != 20

======================================================================
FAIL: test_eval_2 (__main__.TestCollatz)
----------------------------------------------------------------------
Traceback (most recent call last):
  File "TestCollatz.py", line 46, in test_eval_2
    self.assertEqual(v, 125)
AssertionError: 1 != 125

======================================================================
FAIL: test_eval_3 (__main__.TestCollatz)
----------------------------------------------------------------------
Traceback (most recent call last):
  File "TestCollatz.py", line 50, in test_eval_3
    self.assertEqual(v, 89)
AssertionError: 1 != 89

======================================================================
FAIL: test_eval_4 (__main__.TestCollatz)
----------------------------------------------------------------------
Traceback (most recent call last):
  File "TestCollatz.py", line 54, in test_eval_4
    self.assertEqual(v, 174)
AssertionError: 1 != 174

----------------------------------------------------------------------
Ran 7 tests in 0.001s

FAILED (failures=4)
